#usda 1.0
(
    customLayerData = {
        dictionary cameraSettings = {
            dictionary Front = {
                double3 position = (5, 0, 0)
                double radius = 5
            }
            dictionary Perspective = {
                double3 position = (5, 5, 5)
                double3 target = (-3.978038431995401e-8, -3.978038254359717e-8, 7.956076863990802e-8)
            }
            dictionary Right = {
                double3 position = (0, -5, 0)
                double radius = 5
            }
            dictionary Top = {
                double3 position = (0, 0, 5)
                double radius = 5
            }
            string boundCamera = "/OmniverseKit_Persp"
        }
        dictionary omni_layer = {
            string authoring_layer = "./go2.usda"
            dictionary locked = {
            }
            dictionary muteness = {
            }
        }
        dictionary renderSettings = {
        }
    }
    defaultPrim = "go2_description"
    metersPerUnit = 1
    upAxis = "Z"
)

def Xform "go2_description"
{
    quatd xformOp:orient = (1, 0, 0, 0)
    double3 xformOp:scale = (1, 1, 1)
    double3 xformOp:translate = (0, 0, 0)
    uniform token[] xformOpOrder = ["xformOp:translate", "xformOp:orient", "xformOp:scale"]

    def Xform "base" (
        prepend apiSchemas = ["PhysicsRigidBodyAPI", "PhysicsMassAPI", "PhysicsArticulationRootAPI", "PhysxArticulationAPI"]
    )
    {
        point3f physics:centerOfMass = (0.021111997, 0, -0.005366)
        float3 physics:diagonalInertia = (0.024453087, 0.09807712, 0.10702679)
        float physics:mass = 6.921
        quatf physics:principalAxes = (0.999958, 0.0016130266, 0.008992232, -0.0008444425)
        bool physxArticulation:enabledSelfCollisions = 0
        int physxArticulation:solverPositionIterationCount = 32
        int physxArticulation:solverVelocityIterationCount = 16
        quatd xformOp:orient = (1, 0, 0, 0)
        double3 xformOp:scale = (1, 1, 1)
        double3 xformOp:translate = (0, 0, 0)
        uniform token[] xformOpOrder = ["xformOp:translate", "xformOp:orient", "xformOp:scale"]

        def Xform "imu"
        {
            quatd xformOp:orient = (1, 0, 0, 0)
            double3 xformOp:scale = (1, 1, 1)
            double3 xformOp:translate = (-0.02556999959051609, 0, 0.042319998145103455)
            uniform token[] xformOpOrder = ["xformOp:translate", "xformOp:orient", "xformOp:scale"]
        }

        def Xform "radar"
        {
            quatd xformOp:orient = (0.1313159465789795, 0, 0.9913405776023865, 0)
            double3 xformOp:scale = (1, 1, 1)
            double3 xformOp:translate = (0.2894499897956848, 0, -0.046824999153614044)
            uniform token[] xformOpOrder = ["xformOp:translate", "xformOp:orient", "xformOp:scale"]
        }

        def "visuals" (
            instanceable = true
            prepend references = @./Props/instanceable_meshes.usd@</go2_description/base/visuals>
        )
        {
        }

        def "collisions" (
            instanceable = true
            prepend references = @./Props/instanceable_meshes.usd@</go2_description/base/collisions>
        )
        {
        }

        def PhysicsRevoluteJoint "FL_hip_joint" (
            prepend apiSchemas = ["PhysxJointAPI", "PhysicsJointStateAPI:angular", "PhysicsDriveAPI:angular"]
        )
        {
            float drive:angular:physics:damping = 0
            float drive:angular:physics:maxForce = 23.7
            float drive:angular:physics:stiffness = 0
            uniform token drive:angular:physics:type = "force"
            uniform token physics:axis = "X"
            rel physics:body0 = </go2_description/base>
            rel physics:body1 = </go2_description/FL_hip>
            float physics:breakForce = 3.4028235e38
            float physics:breakTorque = 3.4028235e38
            point3f physics:localPos0 = (0.1934, 0.0465, 0)
            point3f physics:localPos1 = (0, 0, 0)
            quatf physics:localRot0 = (1, 0, 0, 0)
            quatf physics:localRot1 = (1, 0, 0, 0)
            float physics:lowerLimit = -60.000134
            float physics:upperLimit = 60.000134
            float physxJoint:jointFriction = 0
            float physxJoint:maxJointVelocity = 1724.603
        }

        def PhysicsRevoluteJoint "FR_hip_joint" (
            prepend apiSchemas = ["PhysxJointAPI", "PhysicsJointStateAPI:angular", "PhysicsDriveAPI:angular"]
        )
        {
            float drive:angular:physics:damping = 0
            float drive:angular:physics:maxForce = 23.7
            float drive:angular:physics:stiffness = 0
            uniform token drive:angular:physics:type = "force"
            uniform token physics:axis = "X"
            rel physics:body0 = </go2_description/base>
            rel physics:body1 = </go2_description/FR_hip>
            float physics:breakForce = 3.4028235e38
            float physics:breakTorque = 3.4028235e38
            point3f physics:localPos0 = (0.1934, -0.0465, 0)
            point3f physics:localPos1 = (0, 0, 0)
            quatf physics:localRot0 = (1, 0, 0, 0)
            quatf physics:localRot1 = (1, 0, 0, 0)
            float physics:lowerLimit = -60.000134
            float physics:upperLimit = 60.000134
            float physxJoint:jointFriction = 0
            float physxJoint:maxJointVelocity = 1724.603
        }

        def PhysicsFixedJoint "Head_upper_joint"
        {
            rel physics:body0 = </go2_description/base>
            rel physics:body1 = </go2_description/Head_upper>
            float physics:breakForce = 3.4028235e38
            float physics:breakTorque = 3.4028235e38
            point3f physics:localPos0 = (0.285, 0, 0.01)
            point3f physics:localPos1 = (0, 0, 0)
            quatf physics:localRot0 = (0.70710677, 0, 0.70710677, 0)
            quatf physics:localRot1 = (0.70710677, 0, 0.70710677, 0)
        }

        def PhysicsRevoluteJoint "RL_hip_joint" (
            prepend apiSchemas = ["PhysxJointAPI", "PhysicsJointStateAPI:angular", "PhysicsDriveAPI:angular"]
        )
        {
            float drive:angular:physics:damping = 0
            float drive:angular:physics:maxForce = 23.7
            float drive:angular:physics:stiffness = 0
            uniform token drive:angular:physics:type = "force"
            uniform token physics:axis = "X"
            rel physics:body0 = </go2_description/base>
            rel physics:body1 = </go2_description/RL_hip>
            float physics:breakForce = 3.4028235e38
            float physics:breakTorque = 3.4028235e38
            point3f physics:localPos0 = (-0.1934, 0.0465, 0)
            point3f physics:localPos1 = (0, 0, 0)
            quatf physics:localRot0 = (1, 0, 0, 0)
            quatf physics:localRot1 = (1, 0, 0, 0)
            float physics:lowerLimit = -60.000134
            float physics:upperLimit = 60.000134
            float physxJoint:jointFriction = 0
            float physxJoint:maxJointVelocity = 1724.603
        }

        def PhysicsRevoluteJoint "RR_hip_joint" (
            prepend apiSchemas = ["PhysxJointAPI", "PhysicsJointStateAPI:angular", "PhysicsDriveAPI:angular"]
        )
        {
            float drive:angular:physics:damping = 0
            float drive:angular:physics:maxForce = 23.7
            float drive:angular:physics:stiffness = 0
            uniform token drive:angular:physics:type = "force"
            uniform token physics:axis = "X"
            rel physics:body0 = </go2_description/base>
            rel physics:body1 = </go2_description/RR_hip>
            float physics:breakForce = 3.4028235e38
            float physics:breakTorque = 3.4028235e38
            point3f physics:localPos0 = (-0.1934, -0.0465, 0)
            point3f physics:localPos1 = (0, 0, 0)
            quatf physics:localRot0 = (1, 0, 0, 0)
            quatf physics:localRot1 = (1, 0, 0, 0)
            float physics:lowerLimit = -60.000134
            float physics:upperLimit = 60.000134
            float physxJoint:jointFriction = 0
            float physxJoint:maxJointVelocity = 1724.603
        }
    }

    def Xform "FL_hip" (
        prepend apiSchemas = ["PhysicsRigidBodyAPI", "PhysicsMassAPI"]
    )
    {
        point3f physics:centerOfMass = (-0.0054, 0.00194, -0.000105)
        float3 physics:diagonalInertia = (0.0004799672, 0.00088402943, 0.0005960034)
        float physics:mass = 0.678
        quatf physics:principalAxes = (0.9999788, -0.0024969478, 0.0047282153, 0.0037199105)
        quatd xformOp:orient = (1, 0, 0, 0)
        double3 xformOp:scale = (1, 1, 1)
        double3 xformOp:translate = (0.19339999556541443, 0.04650000110268593, 0)
        uniform token[] xformOpOrder = ["xformOp:translate", "xformOp:orient", "xformOp:scale"]

        def "visuals" (
            instanceable = true
            prepend references = @./Props/instanceable_meshes.usd@</go2_description/FL_hip/visuals>
        )
        {
        }

        def "collisions" (
            instanceable = true
            prepend references = @./Props/instanceable_meshes.usd@</go2_description/FL_hip/collisions>
        )
        {
        }

        def PhysicsRevoluteJoint "FL_thigh_joint" (
            prepend apiSchemas = ["PhysxJointAPI", "PhysicsJointStateAPI:angular", "PhysicsDriveAPI:angular"]
        )
        {
            float drive:angular:physics:damping = 0
            float drive:angular:physics:maxForce = 23.7
            float drive:angular:physics:stiffness = 0
            uniform token drive:angular:physics:type = "force"
            uniform token physics:axis = "X"
            rel physics:body0 = </go2_description/FL_hip>
            rel physics:body1 = </go2_description/FL_thigh>
            float physics:breakForce = 3.4028235e38
            float physics:breakTorque = 3.4028235e38
            point3f physics:localPos0 = (0, 0.0955, 0)
            point3f physics:localPos1 = (0, 0, 0)
            quatf physics:localRot0 = (0.70710677, 0, 0, 0.70710677)
            quatf physics:localRot1 = (0.70710677, 0, 0, 0.70710677)
            float physics:lowerLimit = -90.000206
            float physics:upperLimit = 200.00237
            float physxJoint:jointFriction = 0
            float physxJoint:maxJointVelocity = 1724.603
        }
    }

    def Xform "FL_thigh" (
        prepend apiSchemas = ["PhysicsRigidBodyAPI", "PhysicsMassAPI"]
    )
    {
        point3f physics:centerOfMass = (-0.00374, -0.0223, -0.0327)
        float3 physics:diagonalInertia = (0.005841487, 0.005949727, 0.00087878696)
        float physics:mass = 1.152
        quatf physics:principalAxes = (0.97662413, 0.074123584, 0.045750134, -0.19651426)
        quatd xformOp:orient = (1, 0, 0, 0)
        double3 xformOp:scale = (1, 1, 1)
        double3 xformOp:translate = (0.19339999556541443, 0.1420000046491623, 0)
        uniform token[] xformOpOrder = ["xformOp:translate", "xformOp:orient", "xformOp:scale"]

        def "visuals" (
            instanceable = true
            prepend references = @./Props/instanceable_meshes.usd@</go2_description/FL_thigh/visuals>
        )
        {
        }

        def "collisions" (
            instanceable = true
            prepend references = @./Props/instanceable_meshes.usd@</go2_description/FL_thigh/collisions>
        )
        {
        }

        def PhysicsRevoluteJoint "FL_calf_joint" (
            prepend apiSchemas = ["PhysxJointAPI", "PhysicsJointStateAPI:angular", "PhysicsDriveAPI:angular"]
        )
        {
            float drive:angular:physics:damping = 0
            float drive:angular:physics:maxForce = 45.43
            float drive:angular:physics:stiffness = 0
            uniform token drive:angular:physics:type = "force"
            uniform token physics:axis = "X"
            rel physics:body0 = </go2_description/FL_thigh>
            rel physics:body1 = </go2_description/FL_calf>
            float physics:breakForce = 3.4028235e38
            float physics:breakTorque = 3.4028235e38
            point3f physics:localPos0 = (0, 0, -0.213)
            point3f physics:localPos1 = (0, 0, 0)
            quatf physics:localRot0 = (0.70710677, 0, 0, 0.70710677)
            quatf physics:localRot1 = (0.70710677, 0, 0, 0.70710677)
            float physics:lowerLimit = -155.99922
            float physics:upperLimit = -48.000107
            float physxJoint:jointFriction = 0
            float physxJoint:maxJointVelocity = 899.5437
        }
    }

    def Xform "FL_calf" (
        prepend apiSchemas = ["PhysicsRigidBodyAPI", "PhysicsMassAPI"]
    )
    {
        point3f physics:centerOfMass = (0.00548, -0.000975, -0.115)
        float3 physics:diagonalInertia = (0.001080271, 0.0011000754, 0.000032553424)
        float physics:mass = 0.154
        quatf physics:principalAxes = (0.999887, 0.003973435, -0.008161128, -0.011986799)
        quatd xformOp:orient = (1, 0, 0, 0)
        double3 xformOp:scale = (1, 1, 1)
        double3 xformOp:translate = (0.19339999556541443, 0.1420000046491623, -0.21299999952316284)
        uniform token[] xformOpOrder = ["xformOp:translate", "xformOp:orient", "xformOp:scale"]

        def Xform "FL_calflower"
        {
            quatd xformOp:orient = (0.9996874928474426, 0, 0.024997396394610405, 0)
            double3 xformOp:scale = (1, 1, 1)
            double3 xformOp:translate = (0.019999999552965164, 0, -0.14800000190734863)
            uniform token[] xformOpOrder = ["xformOp:translate", "xformOp:orient", "xformOp:scale"]
        }

        def "visuals" (
            instanceable = true
            prepend references = @./Props/instanceable_meshes.usd@</go2_description/FL_calf/visuals>
        )
        {
        }

        def "collisions" (
            instanceable = true
            prepend references = @./Props/instanceable_meshes.usd@</go2_description/FL_calf/collisions>
        )
        {
        }

        def PhysicsFixedJoint "FL_foot_joint"
        {
            rel physics:body0 = </go2_description/FL_calf>
            rel physics:body1 = </go2_description/FL_foot>
            float physics:breakForce = 3.4028235e38
            float physics:breakTorque = 3.4028235e38
            point3f physics:localPos0 = (0, 0, -0.213)
            point3f physics:localPos1 = (0, 0, 0)
            quatf physics:localRot0 = (0.70710677, 0, 0.70710677, 0)
            quatf physics:localRot1 = (0.70710677, 0, 0.70710677, 0)
        }
    }

    def Xform "FL_foot" (
        prepend apiSchemas = ["PhysicsRigidBodyAPI", "PhysicsMassAPI"]
    )
    {
        point3f physics:centerOfMass = (0, 0, 0)
        float3 physics:diagonalInertia = (0.0000096, 0.0000096, 0.0000096)
        float physics:mass = 0.04
        quatf physics:principalAxes = (1, 0, 0, 0)
        quatd xformOp:orient = (1, 0, 0, 0)
        double3 xformOp:scale = (1, 1, 1)
        double3 xformOp:translate = (0.19339999556541443, 0.1420000046491623, -0.4259999990463257)
        uniform token[] xformOpOrder = ["xformOp:translate", "xformOp:orient", "xformOp:scale"]

        def "visuals" (
            instanceable = true
            prepend references = @./Props/instanceable_meshes.usd@</go2_description/FL_foot/visuals>
        )
        {
        }

        def "collisions" (
            instanceable = true
            prepend references = @./Props/instanceable_meshes.usd@</go2_description/FL_foot/collisions>
        )
        {
        }
    }

    def Xform "FR_hip" (
        prepend apiSchemas = ["PhysicsRigidBodyAPI", "PhysicsMassAPI"]
    )
    {
        point3f physics:centerOfMass = (-0.0054, -0.00194, -0.000105)
        float3 physics:diagonalInertia = (0.0004799672, 0.00088402943, 0.0005960034)
        float physics:mass = 0.678
        quatf physics:principalAxes = (0.9999788, 0.0024969478, 0.0047282153, -0.0037199105)
        quatd xformOp:orient = (1, 0, 0, 0)
        double3 xformOp:scale = (1, 1, 1)
        double3 xformOp:translate = (0.19339999556541443, -0.04650000110268593, 0)
        uniform token[] xformOpOrder = ["xformOp:translate", "xformOp:orient", "xformOp:scale"]

        def "visuals" (
            instanceable = true
            prepend references = @./Props/instanceable_meshes.usd@</go2_description/FR_hip/visuals>
        )
        {
        }

        def "collisions" (
            instanceable = true
            prepend references = @./Props/instanceable_meshes.usd@</go2_description/FR_hip/collisions>
        )
        {
        }

        def PhysicsRevoluteJoint "FR_thigh_joint" (
            prepend apiSchemas = ["PhysxJointAPI", "PhysicsJointStateAPI:angular", "PhysicsDriveAPI:angular"]
        )
        {
            float drive:angular:physics:damping = 0
            float drive:angular:physics:maxForce = 23.7
            float drive:angular:physics:stiffness = 0
            uniform token drive:angular:physics:type = "force"
            uniform token physics:axis = "X"
            rel physics:body0 = </go2_description/FR_hip>
            rel physics:body1 = </go2_description/FR_thigh>
            float physics:breakForce = 3.4028235e38
            float physics:breakTorque = 3.4028235e38
            point3f physics:localPos0 = (0, -0.0955, 0)
            point3f physics:localPos1 = (0, 0, 0)
            quatf physics:localRot0 = (0.70710677, 0, 0, 0.70710677)
            quatf physics:localRot1 = (0.70710677, 0, 0, 0.70710677)
            float physics:lowerLimit = -90.000206
            float physics:upperLimit = 200.00237
            float physxJoint:jointFriction = 0
            float physxJoint:maxJointVelocity = 1724.603
        }
    }

    def Xform "FR_thigh" (
        prepend apiSchemas = ["PhysicsRigidBodyAPI", "PhysicsMassAPI"]
    )
    {
        point3f physics:centerOfMass = (-0.00374, 0.0223, -0.0327)
        float3 physics:diagonalInertia = (0.005841487, 0.005949727, 0.00087878696)
        float physics:mass = 1.152
        quatf physics:principalAxes = (0.97662413, -0.074123584, 0.045750134, 0.19651426)
        quatd xformOp:orient = (1, 0, 0, 0)
        double3 xformOp:scale = (1, 1, 1)
        double3 xformOp:translate = (0.19339999556541443, -0.1420000046491623, 0)
        uniform token[] xformOpOrder = ["xformOp:translate", "xformOp:orient", "xformOp:scale"]

        def "visuals" (
            instanceable = true
            prepend references = @./Props/instanceable_meshes.usd@</go2_description/FR_thigh/visuals>
        )
        {
        }

        def "collisions" (
            instanceable = true
            prepend references = @./Props/instanceable_meshes.usd@</go2_description/FR_thigh/collisions>
        )
        {
        }

        def PhysicsRevoluteJoint "FR_calf_joint" (
            prepend apiSchemas = ["PhysxJointAPI", "PhysicsJointStateAPI:angular", "PhysicsDriveAPI:angular"]
        )
        {
            float drive:angular:physics:damping = 0
            float drive:angular:physics:maxForce = 45.43
            float drive:angular:physics:stiffness = 0
            uniform token drive:angular:physics:type = "force"
            uniform token physics:axis = "X"
            rel physics:body0 = </go2_description/FR_thigh>
            rel physics:body1 = </go2_description/FR_calf>
            float physics:breakForce = 3.4028235e38
            float physics:breakTorque = 3.4028235e38
            point3f physics:localPos0 = (0, 0, -0.213)
            point3f physics:localPos1 = (0, 0, 0)
            quatf physics:localRot0 = (0.70710677, 0, 0, 0.70710677)
            quatf physics:localRot1 = (0.70710677, 0, 0, 0.70710677)
            float physics:lowerLimit = -155.99922
            float physics:upperLimit = -48.000107
            float physxJoint:jointFriction = 0
            float physxJoint:maxJointVelocity = 899.5437
        }
    }

    def Xform "FR_calf" (
        prepend apiSchemas = ["PhysicsRigidBodyAPI", "PhysicsMassAPI"]
    )
    {
        point3f physics:centerOfMass = (0.00548, 0.000975, -0.115)
        float3 physics:diagonalInertia = (0.001080271, 0.0011000754, 0.000032553424)
        float physics:mass = 0.154
        quatf physics:principalAxes = (0.999887, -0.003973435, -0.008161128, 0.011986799)
        quatd xformOp:orient = (1, 0, 0, 0)
        double3 xformOp:scale = (1, 1, 1)
        double3 xformOp:translate = (0.19339999556541443, -0.1420000046491623, -0.21299999952316284)
        uniform token[] xformOpOrder = ["xformOp:translate", "xformOp:orient", "xformOp:scale"]

        def Xform "FR_calflower"
        {
            quatd xformOp:orient = (0.9996874928474426, 0, 0.024997396394610405, 0)
            double3 xformOp:scale = (1, 1, 1)
            double3 xformOp:translate = (0.019999999552965164, 0, -0.14800000190734863)
            uniform token[] xformOpOrder = ["xformOp:translate", "xformOp:orient", "xformOp:scale"]
        }

        def "visuals" (
            instanceable = true
            prepend references = @./Props/instanceable_meshes.usd@</go2_description/FR_calf/visuals>
        )
        {
        }

        def "collisions" (
            instanceable = true
            prepend references = @./Props/instanceable_meshes.usd@</go2_description/FR_calf/collisions>
        )
        {
        }

        def PhysicsFixedJoint "FR_foot_joint"
        {
            rel physics:body0 = </go2_description/FR_calf>
            rel physics:body1 = </go2_description/FR_foot>
            float physics:breakForce = 3.4028235e38
            float physics:breakTorque = 3.4028235e38
            point3f physics:localPos0 = (0, 0, -0.213)
            point3f physics:localPos1 = (0, 0, 0)
            quatf physics:localRot0 = (0.70710677, 0, 0.70710677, 0)
            quatf physics:localRot1 = (0.70710677, 0, 0.70710677, 0)
        }
    }

    def Xform "FR_foot" (
        prepend apiSchemas = ["PhysicsRigidBodyAPI", "PhysicsMassAPI"]
    )
    {
        point3f physics:centerOfMass = (0, 0, 0)
        float3 physics:diagonalInertia = (0.0000096, 0.0000096, 0.0000096)
        float physics:mass = 0.04
        quatf physics:principalAxes = (1, 0, 0, 0)
        quatd xformOp:orient = (1, 0, 0, 0)
        double3 xformOp:scale = (1, 1, 1)
        double3 xformOp:translate = (0.19339999556541443, -0.1420000046491623, -0.4259999990463257)
        uniform token[] xformOpOrder = ["xformOp:translate", "xformOp:orient", "xformOp:scale"]

        def "visuals" (
            instanceable = true
            prepend references = @./Props/instanceable_meshes.usd@</go2_description/FR_foot/visuals>
        )
        {
        }

        def "collisions" (
            instanceable = true
            prepend references = @./Props/instanceable_meshes.usd@</go2_description/FR_foot/collisions>
        )
        {
        }
    }

    def Xform "Head_upper" (
        prepend apiSchemas = ["PhysicsRigidBodyAPI", "PhysicsMassAPI"]
    )
    {
        point3f physics:centerOfMass = (0, 0, 0)
        float3 physics:diagonalInertia = (0.0000096, 0.0000096, 0.0000096)
        float physics:mass = 0.001
        quatf physics:principalAxes = (1, 0, 0, 0)
        quatd xformOp:orient = (1, 0, 0, 0)
        double3 xformOp:scale = (1, 1, 1)
        double3 xformOp:translate = (0.2849999964237213, 0, 0.009999999776482582)
        uniform token[] xformOpOrder = ["xformOp:translate", "xformOp:orient", "xformOp:scale"]

        def "collisions" (
            instanceable = true
            prepend references = @./Props/instanceable_meshes.usd@</go2_description/Head_upper/collisions>
        )
        {
        }

        def PhysicsFixedJoint "Head_lower_joint"
        {
            rel physics:body0 = </go2_description/Head_upper>
            rel physics:body1 = </go2_description/Head_lower>
            float physics:breakForce = 3.4028235e38
            float physics:breakTorque = 3.4028235e38
            point3f physics:localPos0 = (0.008, 0, -0.07)
            point3f physics:localPos1 = (0, 0, 0)
            quatf physics:localRot0 = (0.70710677, 0, 0.70710677, 0)
            quatf physics:localRot1 = (0.70710677, 0, 0.70710677, 0)
        }
    }

    def Xform "Head_lower" (
        prepend apiSchemas = ["PhysicsRigidBodyAPI", "PhysicsMassAPI"]
    )
    {
        point3f physics:centerOfMass = (0, 0, 0)
        float3 physics:diagonalInertia = (0.0000096, 0.0000096, 0.0000096)
        float physics:mass = 0.001
        quatf physics:principalAxes = (1, 0, 0, 0)
        quatd xformOp:orient = (1, 0, 0, 0)
        double3 xformOp:scale = (1, 1, 1)
        double3 xformOp:translate = (0.2929999828338623, 0, -0.06000000238418579)
        uniform token[] xformOpOrder = ["xformOp:translate", "xformOp:orient", "xformOp:scale"]

        def "collisions" (
            instanceable = true
            prepend references = @./Props/instanceable_meshes.usd@</go2_description/Head_lower/collisions>
        )
        {
        }
    }

    def Xform "RL_hip" (
        prepend apiSchemas = ["PhysicsRigidBodyAPI", "PhysicsMassAPI"]
    )
    {
        point3f physics:centerOfMass = (0.0054, 0.00194, -0.000105)
        float3 physics:diagonalInertia = (0.0004799672, 0.00088402943, 0.0005960034)
        float physics:mass = 0.678
        quatf physics:principalAxes = (0.9999788, -0.0024969478, -0.0047282153, -0.0037199105)
        quatd xformOp:orient = (1, 0, 0, 0)
        double3 xformOp:scale = (1, 1, 1)
        double3 xformOp:translate = (-0.19339999556541443, 0.04650000110268593, 0)
        uniform token[] xformOpOrder = ["xformOp:translate", "xformOp:orient", "xformOp:scale"]

        def "visuals" (
            instanceable = true
            prepend references = @./Props/instanceable_meshes.usd@</go2_description/RL_hip/visuals>
        )
        {
        }

        def "collisions" (
            instanceable = true
            prepend references = @./Props/instanceable_meshes.usd@</go2_description/RL_hip/collisions>
        )
        {
        }

        def PhysicsRevoluteJoint "RL_thigh_joint" (
            prepend apiSchemas = ["PhysxJointAPI", "PhysicsJointStateAPI:angular", "PhysicsDriveAPI:angular"]
        )
        {
            float drive:angular:physics:damping = 0
            float drive:angular:physics:maxForce = 23.7
            float drive:angular:physics:stiffness = 0
            uniform token drive:angular:physics:type = "force"
            uniform token physics:axis = "X"
            rel physics:body0 = </go2_description/RL_hip>
            rel physics:body1 = </go2_description/RL_thigh>
            float physics:breakForce = 3.4028235e38
            float physics:breakTorque = 3.4028235e38
            point3f physics:localPos0 = (0, 0.0955, 0)
            point3f physics:localPos1 = (0, 0, 0)
            quatf physics:localRot0 = (0.70710677, 0, 0, 0.70710677)
            quatf physics:localRot1 = (0.70710677, 0, 0, 0.70710677)
            float physics:lowerLimit = -30.000067
            float physics:upperLimit = 260.0025
            float physxJoint:jointFriction = 0
            float physxJoint:maxJointVelocity = 1724.603
        }
    }

    def Xform "RL_thigh" (
        prepend apiSchemas = ["PhysicsRigidBodyAPI", "PhysicsMassAPI"]
    )
    {
        point3f physics:centerOfMass = (-0.00374, -0.0223, -0.0327)
        float3 physics:diagonalInertia = (0.005841487, 0.005949727, 0.00087878696)
        float physics:mass = 1.152
        quatf physics:principalAxes = (0.97662413, 0.074123584, 0.045750134, -0.19651426)
        quatd xformOp:orient = (1, 0, 0, 0)
        double3 xformOp:scale = (1, 1, 1)
        double3 xformOp:translate = (-0.19339999556541443, 0.1420000046491623, 0)
        uniform token[] xformOpOrder = ["xformOp:translate", "xformOp:orient", "xformOp:scale"]

        def "visuals" (
            instanceable = true
            prepend references = @./Props/instanceable_meshes.usd@</go2_description/RL_thigh/visuals>
        )
        {
        }

        def "collisions" (
            instanceable = true
            prepend references = @./Props/instanceable_meshes.usd@</go2_description/RL_thigh/collisions>
        )
        {
        }

        def PhysicsRevoluteJoint "RL_calf_joint" (
            prepend apiSchemas = ["PhysxJointAPI", "PhysicsJointStateAPI:angular", "PhysicsDriveAPI:angular"]
        )
        {
            float drive:angular:physics:damping = 0
            float drive:angular:physics:maxForce = 45.43
            float drive:angular:physics:stiffness = 0
            uniform token drive:angular:physics:type = "force"
            uniform token physics:axis = "X"
            rel physics:body0 = </go2_description/RL_thigh>
            rel physics:body1 = </go2_description/RL_calf>
            float physics:breakForce = 3.4028235e38
            float physics:breakTorque = 3.4028235e38
            point3f physics:localPos0 = (0, 0, -0.213)
            point3f physics:localPos1 = (0, 0, 0)
            quatf physics:localRot0 = (0.70710677, 0, 0, 0.70710677)
            quatf physics:localRot1 = (0.70710677, 0, 0, 0.70710677)
            float physics:lowerLimit = -155.99922
            float physics:upperLimit = -48.000107
            float physxJoint:jointFriction = 0
            float physxJoint:maxJointVelocity = 899.5437
        }
    }

    def Xform "RL_calf" (
        prepend apiSchemas = ["PhysicsRigidBodyAPI", "PhysicsMassAPI"]
    )
    {
        point3f physics:centerOfMass = (0.00548, -0.000975, -0.115)
        float3 physics:diagonalInertia = (0.001080271, 0.0011000754, 0.000032553424)
        float physics:mass = 0.154
        quatf physics:principalAxes = (0.999887, 0.003973435, -0.008161128, -0.011986799)
        quatd xformOp:orient = (1, 0, 0, 0)
        double3 xformOp:scale = (1, 1, 1)
        double3 xformOp:translate = (-0.19339999556541443, 0.1420000046491623, -0.21299999952316284)
        uniform token[] xformOpOrder = ["xformOp:translate", "xformOp:orient", "xformOp:scale"]

        def Xform "RL_calflower"
        {
            quatd xformOp:orient = (0.9996874928474426, 0, 0.024997396394610405, 0)
            double3 xformOp:scale = (1, 1, 1)
            double3 xformOp:translate = (0.019999999552965164, 0, -0.14800000190734863)
            uniform token[] xformOpOrder = ["xformOp:translate", "xformOp:orient", "xformOp:scale"]
        }

        def "visuals" (
            instanceable = true
            prepend references = @./Props/instanceable_meshes.usd@</go2_description/RL_calf/visuals>
        )
        {
        }

        def "collisions" (
            instanceable = true
            prepend references = @./Props/instanceable_meshes.usd@</go2_description/RL_calf/collisions>
        )
        {
        }

        def PhysicsFixedJoint "RL_foot_joint"
        {
            rel physics:body0 = </go2_description/RL_calf>
            rel physics:body1 = </go2_description/RL_foot>
            float physics:breakForce = 3.4028235e38
            float physics:breakTorque = 3.4028235e38
            point3f physics:localPos0 = (0, 0, -0.213)
            point3f physics:localPos1 = (0, 0, 0)
            quatf physics:localRot0 = (0.70710677, 0, 0.70710677, 0)
            quatf physics:localRot1 = (0.70710677, 0, 0.70710677, 0)
        }
    }

    def Xform "RL_foot" (
        prepend apiSchemas = ["PhysicsRigidBodyAPI", "PhysicsMassAPI"]
    )
    {
        point3f physics:centerOfMass = (0, 0, 0)
        float3 physics:diagonalInertia = (0.0000096, 0.0000096, 0.0000096)
        float physics:mass = 0.04
        quatf physics:principalAxes = (1, 0, 0, 0)
        quatd xformOp:orient = (1, 0, 0, 0)
        double3 xformOp:scale = (1, 1, 1)
        double3 xformOp:translate = (-0.19339999556541443, 0.1420000046491623, -0.4259999990463257)
        uniform token[] xformOpOrder = ["xformOp:translate", "xformOp:orient", "xformOp:scale"]

        def "visuals" (
            instanceable = true
            prepend references = @./Props/instanceable_meshes.usd@</go2_description/RL_foot/visuals>
        )
        {
        }

        def "collisions" (
            instanceable = true
            prepend references = @./Props/instanceable_meshes.usd@</go2_description/RL_foot/collisions>
        )
        {
        }
    }

    def Xform "RR_hip" (
        prepend apiSchemas = ["PhysicsRigidBodyAPI", "PhysicsMassAPI"]
    )
    {
        point3f physics:centerOfMass = (0.0054, -0.00194, -0.000105)
        float3 physics:diagonalInertia = (0.0004799672, 0.00088402943, 0.0005960034)
        float physics:mass = 0.678
        quatf physics:principalAxes = (0.9999788, 0.0024969478, -0.0047282153, 0.0037199105)
        quatd xformOp:orient = (1, 0, 0, 0)
        double3 xformOp:scale = (1, 1, 1)
        double3 xformOp:translate = (-0.19339999556541443, -0.04650000110268593, 0)
        uniform token[] xformOpOrder = ["xformOp:translate", "xformOp:orient", "xformOp:scale"]

        def "visuals" (
            instanceable = true
            prepend references = @./Props/instanceable_meshes.usd@</go2_description/RR_hip/visuals>
        )
        {
        }

        def "collisions" (
            instanceable = true
            prepend references = @./Props/instanceable_meshes.usd@</go2_description/RR_hip/collisions>
        )
        {
        }

        def PhysicsRevoluteJoint "RR_thigh_joint" (
            prepend apiSchemas = ["PhysxJointAPI", "PhysicsJointStateAPI:angular", "PhysicsDriveAPI:angular"]
        )
        {
            float drive:angular:physics:damping = 0
            float drive:angular:physics:maxForce = 23.7
            float drive:angular:physics:stiffness = 0
            uniform token drive:angular:physics:type = "force"
            uniform token physics:axis = "X"
            rel physics:body0 = </go2_description/RR_hip>
            rel physics:body1 = </go2_description/RR_thigh>
            float physics:breakForce = 3.4028235e38
            float physics:breakTorque = 3.4028235e38
            point3f physics:localPos0 = (0, -0.0955, 0)
            point3f physics:localPos1 = (0, 0, 0)
            quatf physics:localRot0 = (0.70710677, 0, 0, 0.70710677)
            quatf physics:localRot1 = (0.70710677, 0, 0, 0.70710677)
            float physics:lowerLimit = -30.000067
            float physics:upperLimit = 260.0025
            float physxJoint:jointFriction = 0
            float physxJoint:maxJointVelocity = 1724.603
        }
    }

    def Xform "RR_thigh" (
        prepend apiSchemas = ["PhysicsRigidBodyAPI", "PhysicsMassAPI"]
    )
    {
        point3f physics:centerOfMass = (-0.00374, 0.0223, -0.0327)
        float3 physics:diagonalInertia = (0.005841487, 0.005949727, 0.00087878696)
        float physics:mass = 1.152
        quatf physics:principalAxes = (0.97662413, -0.074123584, 0.045750134, 0.19651426)
        quatd xformOp:orient = (1, 0, 0, 0)
        double3 xformOp:scale = (1, 1, 1)
        double3 xformOp:translate = (-0.19339999556541443, -0.1420000046491623, 0)
        uniform token[] xformOpOrder = ["xformOp:translate", "xformOp:orient", "xformOp:scale"]

        def "visuals" (
            instanceable = true
            prepend references = @./Props/instanceable_meshes.usd@</go2_description/RR_thigh/visuals>
        )
        {
        }

        def "collisions" (
            instanceable = true
            prepend references = @./Props/instanceable_meshes.usd@</go2_description/RR_thigh/collisions>
        )
        {
        }

        def PhysicsRevoluteJoint "RR_calf_joint" (
            prepend apiSchemas = ["PhysxJointAPI", "PhysicsJointStateAPI:angular", "PhysicsDriveAPI:angular"]
        )
        {
            float drive:angular:physics:damping = 0
            float drive:angular:physics:maxForce = 45.43
            float drive:angular:physics:stiffness = 0
            uniform token drive:angular:physics:type = "force"
            uniform token physics:axis = "X"
            rel physics:body0 = </go2_description/RR_thigh>
            rel physics:body1 = </go2_description/RR_calf>
            float physics:breakForce = 3.4028235e38
            float physics:breakTorque = 3.4028235e38
            point3f physics:localPos0 = (0, 0, -0.213)
            point3f physics:localPos1 = (0, 0, 0)
            quatf physics:localRot0 = (0.70710677, 0, 0, 0.70710677)
            quatf physics:localRot1 = (0.70710677, 0, 0, 0.70710677)
            float physics:lowerLimit = -155.99922
            float physics:upperLimit = -48.000107
            float physxJoint:jointFriction = 0
            float physxJoint:maxJointVelocity = 899.5437
        }
    }

    def Xform "RR_calf" (
        prepend apiSchemas = ["PhysicsRigidBodyAPI", "PhysicsMassAPI"]
    )
    {
        point3f physics:centerOfMass = (0.00548, 0.000975, -0.115)
        float3 physics:diagonalInertia = (0.001080271, 0.0011000754, 0.000032553424)
        float physics:mass = 0.154
        quatf physics:principalAxes = (0.999887, -0.003973435, -0.008161128, 0.011986799)
        quatd xformOp:orient = (1, 0, 0, 0)
        double3 xformOp:scale = (1, 1, 1)
        double3 xformOp:translate = (-0.19339999556541443, -0.1420000046491623, -0.21299999952316284)
        uniform token[] xformOpOrder = ["xformOp:translate", "xformOp:orient", "xformOp:scale"]

        def Xform "RR_calflower"
        {
            quatd xformOp:orient = (0.9996874928474426, 0, 0.024997396394610405, 0)
            double3 xformOp:scale = (1, 1, 1)
            double3 xformOp:translate = (0.019999999552965164, 0, -0.14800000190734863)
            uniform token[] xformOpOrder = ["xformOp:translate", "xformOp:orient", "xformOp:scale"]
        }

        def "visuals" (
            instanceable = true
            prepend references = @./Props/instanceable_meshes.usd@</go2_description/RR_calf/visuals>
        )
        {
        }

        def "collisions" (
            instanceable = true
            prepend references = @./Props/instanceable_meshes.usd@</go2_description/RR_calf/collisions>
        )
        {
        }

        def PhysicsFixedJoint "RR_foot_joint"
        {
            rel physics:body0 = </go2_description/RR_calf>
            rel physics:body1 = </go2_description/RR_foot>
            float physics:breakForce = 3.4028235e38
            float physics:breakTorque = 3.4028235e38
            point3f physics:localPos0 = (0, 0, -0.213)
            point3f physics:localPos1 = (0, 0, 0)
            quatf physics:localRot0 = (0.70710677, 0, 0.70710677, 0)
            quatf physics:localRot1 = (0.70710677, 0, 0.70710677, 0)
        }
    }

    def Xform "RR_foot" (
        prepend apiSchemas = ["PhysicsRigidBodyAPI", "PhysicsMassAPI"]
    )
    {
        point3f physics:centerOfMass = (0, 0, 0)
        float3 physics:diagonalInertia = (0.0000096, 0.0000096, 0.0000096)
        float physics:mass = 0.04
        quatf physics:principalAxes = (1, 0, 0, 0)
        quatd xformOp:orient = (1, 0, 0, 0)
        double3 xformOp:scale = (1, 1, 1)
        double3 xformOp:translate = (-0.19339999556541443, -0.1420000046491623, -0.4259999990463257)
        uniform token[] xformOpOrder = ["xformOp:translate", "xformOp:orient", "xformOp:scale"]

        def "visuals" (
            instanceable = true
            prepend references = @./Props/instanceable_meshes.usd@</go2_description/RR_foot/visuals>
        )
        {
        }

        def "collisions" (
            instanceable = true
            prepend references = @./Props/instanceable_meshes.usd@</go2_description/RR_foot/collisions>
        )
        {
        }
    }
}

def "Render" (
    hide_in_stage_window = true
    no_delete = true
)
{
    def "OmniverseKit"
    {
        def "HydraTextures" (
            hide_in_stage_window = true
            no_delete = true
        )
        {
            def RenderProduct "omni_kit_widget_viewport_ViewportTexture_0" (
                prepend apiSchemas = ["OmniRtxSettingsCommonAdvancedAPI_1", "OmniRtxSettingsRtAdvancedAPI_1", "OmniRtxSettingsPtAdvancedAPI_1", "OmniRtxPostColorGradingAPI_1", "OmniRtxPostChromaticAberrationAPI_1", "OmniRtxPostBloomPhysicalAPI_1", "OmniRtxPostMatteObjectAPI_1", "OmniRtxPostCompositingAPI_1", "OmniRtxPostDofAPI_1", "OmniRtxPostMotionBlurAPI_1", "OmniRtxPostTvNoiseAPI_1", "OmniRtxPostTonemapIrayReinhardAPI_1", "OmniRtxPostDebugSettingsAPI_1", "OmniRtxDebugSettingsAPI_1"]
                hide_in_stage_window = true
                no_delete = true
            )
            {
                rel camera = </OmniverseKit_Persp>
                token omni:rtx:background:source:texture:textureMode = "repeatMirrored"
                token omni:rtx:background:source:type = "domeLight"
                bool omni:rtx:dlss:frameGeneration = 0
                string omni:rtx:material:db:rtSensorNameToIdMap = "DefaultMaterial:0;AsphaltStandardMaterial:1;AsphaltWeatheredMaterial:2;VegetationGrassMaterial:3;WaterStandardMaterial:4;GlassStandardMaterial:5;FiberGlassMaterial:6;MetalAlloyMaterial:7;MetalAluminumMaterial:8;MetalAluminumOxidizedMaterial:9;PlasticStandardMaterial:10;RetroMarkingsMaterial:11;RetroSignMaterial:12;RubberStandardMaterial:13;SoilClayMaterial:14;ConcreteRoughMaterial:15;ConcreteSmoothMaterial:16;OakTreeBarkMaterial:17;FabricStandardMaterial:18;PlexiGlassStandardMaterial:19;MetalSilverMaterial:20"
                bool omni:rtx:material:db:syncLoads = 1
                bool omni:rtx:post:registeredCompositing:invertColorCorrection = 1
                bool omni:rtx:post:registeredCompositing:invertToneMap = 1
                bool omni:rtx:pt:lightcache:cached:dontResolveConflicts = 1
                int omni:rtx:pt:maxSamplesPerLaunch = 2073600
                int omni:rtx:pt:mgpu:maxPixelsPerRegionExponent = 12
                color3f omni:rtx:rt:ambientLight:color = (0.1, 0.1, 0.1)
                bool omni:rtx:rt:demoire = 0
                bool omni:rtx:rt:lightcache:spatialCache:dontResolveConflicts = 1
                bool omni:rtx:scene:hydra:materialSyncLoads = 1
                bool omni:rtx:scene:hydra:mdlMaterialWarmup = 1
                uint omni:rtx:viewTile:limit = 4294967295
                rel orderedVars = </Render/Vars/LdrColor>
                custom bool overrideClipRange = 0
                uniform int2 resolution = (1280, 720)
            }
        }
    }

    def RenderSettings "OmniverseGlobalRenderSettings" (
        prepend apiSchemas = ["OmniRtxSettingsGlobalRtAdvancedAPI_1", "OmniRtxSettingsGlobalPtAdvancedAPI_1"]
        no_delete = true
    )
    {
        rel products = </Render/OmniverseKit/HydraTextures/omni_kit_widget_viewport_ViewportTexture_0>
    }

    def "Vars"
    {
        def RenderVar "LdrColor" (
            hide_in_stage_window = true
            no_delete = true
        )
        {
            uniform string sourceName = "LdrColor"
        }
    }
}

